Traceback (most recent call last):
  File "/usr/share/miniconda3/envs/test/lib/python3.11/site-packages/jupyter_cache/executors/utils.py", line 58, in single_nb_execution
    executenb(
  File "/usr/share/miniconda3/envs/test/lib/python3.11/site-packages/nbclient/client.py", line 1305, in execute
    return NotebookClient(nb=nb, resources=resources, km=km, **kwargs).execute()
           ^^^^^^^^^^^^^^^^^^^^^^^^^^^^^^^^^^^^^^^^^^^^^^^^^^^^^^^^^^^^^^^^^^^^^
  File "/usr/share/miniconda3/envs/test/lib/python3.11/site-packages/jupyter_core/utils/__init__.py", line 98, in wrapped
    return loop.run_until_complete(inner)
           ^^^^^^^^^^^^^^^^^^^^^^^^^^^^^^
  File "/usr/share/miniconda3/envs/test/lib/python3.11/asyncio/base_events.py", line 653, in run_until_complete
    return future.result()
           ^^^^^^^^^^^^^^^
  File "/usr/share/miniconda3/envs/test/lib/python3.11/site-packages/nbclient/client.py", line 705, in async_execute
    await self.async_execute_cell(
  File "/usr/share/miniconda3/envs/test/lib/python3.11/site-packages/nbclient/client.py", line 1058, in async_execute_cell
    await self._check_raise_for_error(cell, cell_index, exec_reply)
  File "/usr/share/miniconda3/envs/test/lib/python3.11/site-packages/nbclient/client.py", line 914, in _check_raise_for_error
    raise CellExecutionError.from_cell_and_msg(cell, exec_reply_content)
nbclient.exceptions.CellExecutionError: An error occurred while executing the following cell:
------------------
EllipticCurve('11a1')
------------------


[0;31m---------------------------------------------------------------------------[0m
[0;31mFeatureNotPresentError[0m                    Traceback (most recent call last)
Cell [0;32mIn[1], line 1[0m
[0;32m----> 1[0m [43mEllipticCurve[49m[43m([49m[38;5;124;43m'[39;49m[38;5;124;43m11a1[39;49m[38;5;124;43m'[39;49m[43m)[49m

File [0;32m/usr/share/miniconda3/envs/test/lib/python3.11/site-packages/sage/structure/factory.pyx:371[0m, in [0;36msage.structure.factory.UniqueFactory.__call__ (build/cythonized/sage/structure/factory.c:4155)[0;34m()[0m
[1;32m    369[0m     False
[1;32m    370[0m """
[0;32m--> 371[0m key, kwds = self.create_key_and_extra_args(*args, **kwds)
[1;32m    372[0m version = self.get_version(sage_version)
[1;32m    373[0m return self.get_object(version, key, kwds)

File [0;32m/usr/share/miniconda3/envs/test/lib/python3.11/site-packages/sage/schemes/elliptic_curves/constructor.py:440[0m, in [0;36mEllipticCurveFactory.create_key_and_extra_args[0;34m(self, x, y, j, minimal_twist, **kwds)[0m
[1;32m    437[0m [38;5;28;01mif[39;00m [38;5;28misinstance[39m(x, [38;5;28mstr[39m):
[1;32m    438[0m     [38;5;66;03m# Interpret x as a Cremona or LMFDB label.[39;00m
[1;32m    439[0m     [38;5;28;01mfrom[39;00m [38;5;21;01msage[39;00m[38;5;21;01m.[39;00m[38;5;21;01mdatabases[39;00m[38;5;21;01m.[39;00m[38;5;21;01mcremona[39;00m [38;5;28;01mimport[39;00m CremonaDatabase
[0;32m--> 440[0m     x, data [38;5;241m=[39m [43mCremonaDatabase[49m[43m([49m[43m)[49m[38;5;241m.[39mcoefficients_and_data(x)
[1;32m    441[0m     [38;5;66;03m# User-provided keywords may override database entries.[39;00m
[1;32m    442[0m     data[38;5;241m.[39mupdate(kwds)

File [0;32m/usr/share/miniconda3/envs/test/lib/python3.11/site-packages/sage/databases/cremona.py:1728[0m, in [0;36mCremonaDatabase[0;34m(name, mini, set_global)[0m
[1;32m   1725[0m     [38;5;28;01mraise[39;00m [38;5;167;01mValueError[39;00m([38;5;124m'[39m[38;5;124mmini must be set as either True or False[39m[38;5;124m'[39m)
[1;32m   1727[0m [38;5;28;01mif[39;00m mini:
[0;32m-> 1728[0m     [38;5;28;01mreturn[39;00m [43mMiniCremonaDatabase[49m[43m([49m[43mname[49m[43m)[49m
[1;32m   1729[0m [38;5;28;01melse[39;00m:
[1;32m   1730[0m     [38;5;28;01mreturn[39;00m LargeCremonaDatabase(name)

File [0;32m/usr/share/miniconda3/envs/test/lib/python3.11/site-packages/sage/databases/cremona.py:672[0m, in [0;36mMiniCremonaDatabase.__init__[0;34m(self, name, read_only, build)[0m
[1;32m    670[0m [38;5;28mself[39m[38;5;241m.[39mname [38;5;241m=[39m name
[1;32m    671[0m name [38;5;241m=[39m name[38;5;241m.[39mreplace([38;5;124m'[39m[38;5;124m [39m[38;5;124m'[39m, [38;5;124m'[39m[38;5;124m_[39m[38;5;124m'[39m)
[0;32m--> 672[0m db_path [38;5;241m=[39m [43mDatabaseCremona[49m[43m([49m[43mname[49m[38;5;241;43m=[39;49m[43mname[49m[43m)[49m[38;5;241;43m.[39;49m[43mabsolute_filename[49m[43m([49m[43m)[49m
[1;32m    673[0m [38;5;28;01mif[39;00m build:
[1;32m    674[0m     [38;5;28;01mif[39;00m read_only:

File [0;32m/usr/share/miniconda3/envs/test/lib/python3.11/site-packages/sage/features/__init__.py:853[0m, in [0;36mStaticFile.absolute_filename[0;34m(self)[0m
[1;32m    851[0m         [38;5;28;01mreturn[39;00m os[38;5;241m.[39mpath[38;5;241m.[39mabspath(path)
[1;32m    852[0m reason [38;5;241m=[39m [38;5;124m"[39m[38;5;132;01m{filename!r}[39;00m[38;5;124m not found in any of [39m[38;5;132;01m{search_path}[39;00m[38;5;124m"[39m[38;5;241m.[39mformat(filename[38;5;241m=[39m[38;5;28mself[39m[38;5;241m.[39mfilename, search_path[38;5;241m=[39m[38;5;28mself[39m[38;5;241m.[39msearch_path)
[0;32m--> 853[0m [38;5;28;01mraise[39;00m FeatureNotPresentError([38;5;28mself[39m, reason[38;5;241m=[39mreason, resolution[38;5;241m=[39m[38;5;28mself[39m[38;5;241m.[39mresolution())

[0;31mFeatureNotPresentError[0m: database_cremona_mini_ellcurve is not available.
'cremona_mini.db' not found in any of ['/usr/share/miniconda3/envs/test/share/cremona']
No equivalent system packages for pip are known to Sage.
Further installation instructions might be available at https://github.com/JohnCremona/ecdata.

